{
 "cells": [
  {
   "cell_type": "code",
   "execution_count": 1,
   "metadata": {},
   "outputs": [],
   "source": [
    "import os"
   ]
  },
  {
   "cell_type": "code",
   "execution_count": 2,
   "metadata": {},
   "outputs": [
    {
     "data": {
      "text/plain": [
       "'c:\\\\Users\\\\NITRO\\\\Desktop\\\\MIAAD\\\\DeepLearning\\\\Cnn-Classifier\\\\research'"
      ]
     },
     "execution_count": 2,
     "metadata": {},
     "output_type": "execute_result"
    }
   ],
   "source": [
    "%pwd"
   ]
  },
  {
   "cell_type": "code",
   "execution_count": 3,
   "metadata": {},
   "outputs": [],
   "source": [
    "os.chdir(\"../\")"
   ]
  },
  {
   "cell_type": "code",
   "execution_count": 4,
   "metadata": {},
   "outputs": [
    {
     "data": {
      "text/plain": [
       "'c:\\\\Users\\\\NITRO\\\\Desktop\\\\MIAAD\\\\DeepLearning\\\\Cnn-Classifier'"
      ]
     },
     "execution_count": 4,
     "metadata": {},
     "output_type": "execute_result"
    }
   ],
   "source": [
    "%pwd"
   ]
  },
  {
   "cell_type": "code",
   "execution_count": 5,
   "metadata": {},
   "outputs": [
    {
     "name": "stdout",
     "output_type": "stream",
     "text": [
      "WARNING:tensorflow:From c:\\Users\\NITRO\\anaconda3\\envs\\cnnClassifier\\lib\\site-packages\\keras\\src\\losses.py:2976: The name tf.losses.sparse_softmax_cross_entropy is deprecated. Please use tf.compat.v1.losses.sparse_softmax_cross_entropy instead.\n",
      "\n"
     ]
    }
   ],
   "source": [
    "import tensorflow as tf"
   ]
  },
  {
   "cell_type": "code",
   "execution_count": 6,
   "metadata": {},
   "outputs": [],
   "source": [
    "from dataclasses import dataclass\n",
    "from pathlib import Path\n",
    "\n",
    "@dataclass\n",
    "class EvaluationConfig:\n",
    "    path_of_model: Path\n",
    "    training_data: Path\n",
    "    all_params: dict\n",
    "    params_image_size: list\n",
    "    params_batch_size: int\n",
    "    "
   ]
  },
  {
   "cell_type": "code",
   "execution_count": 7,
   "metadata": {},
   "outputs": [],
   "source": [
    "from src.cnnClassifier.constants import *\n",
    "from src.cnnClassifier.utils.common import read_yaml, create_directories, save_json"
   ]
  },
  {
   "cell_type": "code",
   "execution_count": 8,
   "metadata": {},
   "outputs": [],
   "source": [
    "class ConfigurationManager:\n",
    "    def __init__(\n",
    "        self, \n",
    "        config_filepath = CONFIG_FILE_PATH,\n",
    "        params_filepath = PARAMS_FILE_PATH):\n",
    "        self.config = read_yaml(config_filepath)\n",
    "        self.params = read_yaml(params_filepath)\n",
    "        create_directories([self.config.artifacts_root])\n",
    "\n",
    "    def get_valuation_config(self) ->EvaluationConfig:\n",
    "        eval_config = EvaluationConfig(\n",
    "            path_of_model = \"artifacts/training/model.h5\",\n",
    "            training_data=\"artifacts/data_ingestion/cats_vs_dogs\",\n",
    "            all_params=self.params,\n",
    "            params_image_size=self.config.IMAGE_SIZE,\n",
    "            params_batch_size=self.config.BATCH_SIZE\n",
    "        )\n",
    "        return eval_config"
   ]
  },
  {
   "cell_type": "code",
   "execution_count": 9,
   "metadata": {},
   "outputs": [],
   "source": [
    "from urllib.parse import urlparse"
   ]
  },
  {
   "cell_type": "code",
   "execution_count": 10,
   "metadata": {},
   "outputs": [],
   "source": [
    "class Evaluation:\n",
    "    def __init__(self, config: EvaluationConfig):\n",
    "        self.config = config\n",
    "\n",
    "    \n",
    "    def _valid_generator(self):\n",
    "\n",
    "        datagenerator_kwargs = dict(\n",
    "            rescale = 1./255,\n",
    "            validation_split=0.30\n",
    "        )\n",
    "\n",
    "        dataflow_kwargs = dict(\n",
    "            target_size=self.config.params_image_size[:-1],\n",
    "            batch_size=self.config.params_batch_size,\n",
    "            interpolation=\"bilinear\"\n",
    "        )\n",
    "\n",
    "        valid_datagenerator = tf.keras.preprocessing.image.ImageDataGenerator(\n",
    "            **datagenerator_kwargs\n",
    "        )\n",
    "\n",
    "        self.valid_generator = valid_datagenerator.flow_from_directory(\n",
    "            directory=self.config.training_data,\n",
    "            subset=\"validation\",\n",
    "            shuffle=False,\n",
    "            **dataflow_kwargs\n",
    "        )\n",
    "\n",
    "    \n",
    "    @staticmethod\n",
    "    def load_model(path: Path) -> tf.keras.Model:\n",
    "        return tf.keras.models.load_model(path)\n",
    "    \n",
    "\n",
    "    def evaluation(self):\n",
    "        self.model = self.load_model(self.config.path_of_model)\n",
    "        self._valid_generator()\n",
    "        self.score = model.evaluate(self.valid_generator)\n",
    "\n",
    "    \n",
    "    def save_score(self):\n",
    "        scores = {\"loss\": self.score[0], \"accuracy\": self.score[1]}\n",
    "        save_json(path=Path(\"scores.json\"), data=scores)"
   ]
  },
  {
   "cell_type": "code",
   "execution_count": 11,
   "metadata": {},
   "outputs": [
    {
     "name": "stdout",
     "output_type": "stream",
     "text": [
      "================================================\n",
      "file have been opened\n",
      "file puted in configBox\n",
      "{'artifacts_root': 'artifacts', 'data_ingestion': {'root_dir': 'artifacts/data_ingestion', 'source_url': 'https://github.com/abdelkhalek-haddany/DataMiningProject/blob/main/DMDatasets.zip', 'local_data_file': 'artifacts/data_ingestion/data.zip', 'unzip_dir': 'artifacts/data_ingestion'}, 'prepare_base_model': {'root_dir': 'artifacts/prepare_base_model', 'base_model_path': 'artifacts/prepare_base_model/base_model.h5', 'updated_base_model_path': 'artifacts/prepare_base_model/base_model_updated.h5'}, 'prepare_callbacks': {'root_dir': 'artifacts/prepare_callbacks', 'tensorboard_root_log_dir': 'artifacts/prepare_callbacks/tensorboard_log_dir', 'checkpoint_model_filepath': 'artifacts/prepare_callbacks/checkpoint_dir/model.h5'}, 'training': {'root_dir': 'artifacts/training', 'trained_model_path': 'artifacts/training/model.h5'}}\n",
      "================================================\n",
      "file have been opened\n",
      "file puted in configBox\n",
      "{'AUGMENTATION': True, 'IMAGE_SIZE': [224, 224, 3], 'BATCH_SIZE': 16, 'INCLUDE_TOP': False, 'EPOCHS': 1, 'CLASSES': 2, 'WEIGHTS': 'imagenet', 'LEARNING_RATE': 0.01}\n",
      "[2024-01-20 18:29:04,029: INFO: common: created directory at: artifacts]\n"
     ]
    },
    {
     "ename": "BoxKeyError",
     "evalue": "\"'ConfigBox' object has no attribute 'image_size'\"",
     "output_type": "error",
     "traceback": [
      "\u001b[1;31m---------------------------------------------------------------------------\u001b[0m",
      "\u001b[1;31mKeyError\u001b[0m                                  Traceback (most recent call last)",
      "File \u001b[1;32mc:\\Users\\NITRO\\anaconda3\\envs\\cnnClassifier\\lib\\site-packages\\box\\box.py:503\u001b[0m, in \u001b[0;36mbox.box.Box.__getitem__\u001b[1;34m()\u001b[0m\n",
      "\u001b[1;31mKeyError\u001b[0m: 'IMAGE_SIZE'",
      "\nThe above exception was the direct cause of the following exception:\n",
      "\u001b[1;31mBoxKeyError\u001b[0m                               Traceback (most recent call last)",
      "File \u001b[1;32mc:\\Users\\NITRO\\anaconda3\\envs\\cnnClassifier\\lib\\site-packages\\box\\box.py:536\u001b[0m, in \u001b[0;36mbox.box.Box.__getattr__\u001b[1;34m()\u001b[0m\n",
      "File \u001b[1;32mc:\\Users\\NITRO\\anaconda3\\envs\\cnnClassifier\\lib\\site-packages\\box\\box.py:524\u001b[0m, in \u001b[0;36mbox.box.Box.__getitem__\u001b[1;34m()\u001b[0m\n",
      "\u001b[1;31mBoxKeyError\u001b[0m: \"'IMAGE_SIZE'\"",
      "\nDuring handling of the above exception, another exception occurred:\n",
      "\u001b[1;31mAttributeError\u001b[0m                            Traceback (most recent call last)",
      "File \u001b[1;32mc:\\Users\\NITRO\\anaconda3\\envs\\cnnClassifier\\lib\\site-packages\\box\\box.py:538\u001b[0m, in \u001b[0;36mbox.box.Box.__getattr__\u001b[1;34m()\u001b[0m\n",
      "\u001b[1;31mAttributeError\u001b[0m: 'ConfigBox' object has no attribute 'IMAGE_SIZE'",
      "\nThe above exception was the direct cause of the following exception:\n",
      "\u001b[1;31mBoxKeyError\u001b[0m                               Traceback (most recent call last)",
      "File \u001b[1;32mc:\\Users\\NITRO\\anaconda3\\envs\\cnnClassifier\\lib\\site-packages\\box\\config_box.py:28\u001b[0m, in \u001b[0;36mbox.config_box.ConfigBox.__getattr__\u001b[1;34m()\u001b[0m\n",
      "File \u001b[1;32mc:\\Users\\NITRO\\anaconda3\\envs\\cnnClassifier\\lib\\site-packages\\box\\box.py:552\u001b[0m, in \u001b[0;36mbox.box.Box.__getattr__\u001b[1;34m()\u001b[0m\n",
      "\u001b[1;31mBoxKeyError\u001b[0m: \"'ConfigBox' object has no attribute 'IMAGE_SIZE'\"",
      "\nDuring handling of the above exception, another exception occurred:\n",
      "\u001b[1;31mKeyError\u001b[0m                                  Traceback (most recent call last)",
      "File \u001b[1;32mc:\\Users\\NITRO\\anaconda3\\envs\\cnnClassifier\\lib\\site-packages\\box\\box.py:503\u001b[0m, in \u001b[0;36mbox.box.Box.__getitem__\u001b[1;34m()\u001b[0m\n",
      "\u001b[1;31mKeyError\u001b[0m: 'image_size'",
      "\nThe above exception was the direct cause of the following exception:\n",
      "\u001b[1;31mBoxKeyError\u001b[0m                               Traceback (most recent call last)",
      "File \u001b[1;32mc:\\Users\\NITRO\\anaconda3\\envs\\cnnClassifier\\lib\\site-packages\\box\\box.py:536\u001b[0m, in \u001b[0;36mbox.box.Box.__getattr__\u001b[1;34m()\u001b[0m\n",
      "File \u001b[1;32mc:\\Users\\NITRO\\anaconda3\\envs\\cnnClassifier\\lib\\site-packages\\box\\box.py:524\u001b[0m, in \u001b[0;36mbox.box.Box.__getitem__\u001b[1;34m()\u001b[0m\n",
      "\u001b[1;31mBoxKeyError\u001b[0m: \"'image_size'\"",
      "\nDuring handling of the above exception, another exception occurred:\n",
      "\u001b[1;31mAttributeError\u001b[0m                            Traceback (most recent call last)",
      "File \u001b[1;32mc:\\Users\\NITRO\\anaconda3\\envs\\cnnClassifier\\lib\\site-packages\\box\\box.py:538\u001b[0m, in \u001b[0;36mbox.box.Box.__getattr__\u001b[1;34m()\u001b[0m\n",
      "\u001b[1;31mAttributeError\u001b[0m: 'ConfigBox' object has no attribute 'image_size'",
      "\nThe above exception was the direct cause of the following exception:\n",
      "\u001b[1;31mBoxKeyError\u001b[0m                               Traceback (most recent call last)",
      "Cell \u001b[1;32mIn[11], line 8\u001b[0m\n\u001b[0;32m      6\u001b[0m     evaluation\u001b[38;5;241m.\u001b[39msave_score()\n\u001b[0;32m      7\u001b[0m \u001b[38;5;28;01mexcept\u001b[39;00m \u001b[38;5;167;01mException\u001b[39;00m \u001b[38;5;28;01mas\u001b[39;00m e:\n\u001b[1;32m----> 8\u001b[0m     \u001b[38;5;28;01mraise\u001b[39;00m e\n",
      "Cell \u001b[1;32mIn[11], line 3\u001b[0m\n\u001b[0;32m      1\u001b[0m \u001b[38;5;28;01mtry\u001b[39;00m:\n\u001b[0;32m      2\u001b[0m     config \u001b[38;5;241m=\u001b[39m ConfigurationManager()\n\u001b[1;32m----> 3\u001b[0m     val_config \u001b[38;5;241m=\u001b[39m \u001b[43mconfig\u001b[49m\u001b[38;5;241;43m.\u001b[39;49m\u001b[43mget_valuation_config\u001b[49m\u001b[43m(\u001b[49m\u001b[43m)\u001b[49m\n\u001b[0;32m      4\u001b[0m     evaluation \u001b[38;5;241m=\u001b[39m Evaluation(val_config)\n\u001b[0;32m      5\u001b[0m     evaluation\u001b[38;5;241m.\u001b[39mevaluation()\n",
      "Cell \u001b[1;32mIn[8], line 15\u001b[0m, in \u001b[0;36mConfigurationManager.get_valuation_config\u001b[1;34m(self)\u001b[0m\n\u001b[0;32m     10\u001b[0m \u001b[38;5;28;01mdef\u001b[39;00m \u001b[38;5;21mget_valuation_config\u001b[39m(\u001b[38;5;28mself\u001b[39m) \u001b[38;5;241m-\u001b[39m\u001b[38;5;241m>\u001b[39mEvaluationConfig:\n\u001b[0;32m     11\u001b[0m     eval_config \u001b[38;5;241m=\u001b[39m EvaluationConfig(\n\u001b[0;32m     12\u001b[0m         path_of_model \u001b[38;5;241m=\u001b[39m \u001b[38;5;124m\"\u001b[39m\u001b[38;5;124martifacts/training/model.h5\u001b[39m\u001b[38;5;124m\"\u001b[39m,\n\u001b[0;32m     13\u001b[0m         training_data\u001b[38;5;241m=\u001b[39m\u001b[38;5;124m\"\u001b[39m\u001b[38;5;124martifacts/data_ingestion/cats_vs_dogs\u001b[39m\u001b[38;5;124m\"\u001b[39m,\n\u001b[0;32m     14\u001b[0m         all_params\u001b[38;5;241m=\u001b[39m\u001b[38;5;28mself\u001b[39m\u001b[38;5;241m.\u001b[39mparams,\n\u001b[1;32m---> 15\u001b[0m         params_image_size\u001b[38;5;241m=\u001b[39m\u001b[38;5;28;43mself\u001b[39;49m\u001b[38;5;241;43m.\u001b[39;49m\u001b[43mconfig\u001b[49m\u001b[38;5;241;43m.\u001b[39;49m\u001b[43mIMAGE_SIZE\u001b[49m,\n\u001b[0;32m     16\u001b[0m         params_batch_size\u001b[38;5;241m=\u001b[39m\u001b[38;5;28mself\u001b[39m\u001b[38;5;241m.\u001b[39mconfig\u001b[38;5;241m.\u001b[39mBATCH_SIZE\n\u001b[0;32m     17\u001b[0m     )\n\u001b[0;32m     18\u001b[0m     \u001b[38;5;28;01mreturn\u001b[39;00m eval_config\n",
      "File \u001b[1;32mc:\\Users\\NITRO\\anaconda3\\envs\\cnnClassifier\\lib\\site-packages\\box\\config_box.py:30\u001b[0m, in \u001b[0;36mbox.config_box.ConfigBox.__getattr__\u001b[1;34m()\u001b[0m\n",
      "File \u001b[1;32mc:\\Users\\NITRO\\anaconda3\\envs\\cnnClassifier\\lib\\site-packages\\box\\box.py:552\u001b[0m, in \u001b[0;36mbox.box.Box.__getattr__\u001b[1;34m()\u001b[0m\n",
      "\u001b[1;31mBoxKeyError\u001b[0m: \"'ConfigBox' object has no attribute 'image_size'\""
     ]
    }
   ],
   "source": [
    "try:\n",
    "    config = ConfigurationManager()\n",
    "    val_config = config.get_valuation_config()\n",
    "    evaluation = Evaluation(val_config)\n",
    "    evaluation.evaluation()\n",
    "    evaluation.save_score()\n",
    "except Exception as e:\n",
    "    raise e"
   ]
  },
  {
   "cell_type": "code",
   "execution_count": null,
   "metadata": {},
   "outputs": [],
   "source": []
  },
  {
   "cell_type": "code",
   "execution_count": null,
   "metadata": {},
   "outputs": [],
   "source": []
  }
 ],
 "metadata": {
  "kernelspec": {
   "display_name": "cnnClassifier",
   "language": "python",
   "name": "python3"
  },
  "language_info": {
   "codemirror_mode": {
    "name": "ipython",
    "version": 3
   },
   "file_extension": ".py",
   "mimetype": "text/x-python",
   "name": "python",
   "nbconvert_exporter": "python",
   "pygments_lexer": "ipython3",
   "version": "3.9.12"
  }
 },
 "nbformat": 4,
 "nbformat_minor": 2
}
